2022-11-12 06:26:32.879 WARNING (SyncWorker_0) [homeassistant.loader] We found a custom integration hacs which has not been tested by Home Assistant. This component might cause stability problems, be sure to disable it if you experience issues with Home Assistant
2022-11-12 06:26:32.881 WARNING (SyncWorker_0) [homeassistant.loader] We found a custom integration xiaomi_miot which has not been tested by Home Assistant. This component might cause stability problems, be sure to disable it if you experience issues with Home Assistant
2022-11-12 06:26:32.883 WARNING (SyncWorker_0) [homeassistant.loader] We found a custom integration xiaomi_cloud_map_extractor which has not been tested by Home Assistant. This component might cause stability problems, be sure to disable it if you experience issues with Home Assistant
2022-11-12 06:26:54.091 ERROR (MainThread) [homeassistant.config] Invalid config for [automation]: Unable to determine action @ data['action'][3]. Got None. (See ?, line ?). 
2022-11-12 06:26:55.961 ERROR (MainThread) [homeassistant.components.camera] Entity id already exists - ignoring: camera.xiaomi_cloud_map_extractor
2022-11-12 06:27:41.814 ERROR (MainThread) [homeassistant.helpers.entity] Update for vacuum.roidmi_v60_8a32_robot_cleaner fails
Traceback (most recent call last):
  File "/usr/local/lib/python3.10/site-packages/miio/protocol.py", line 198, in _decode
    decoded = quirk(decrypted).decode("utf-8")
UnicodeDecodeError: 'utf-8' codec can't decode byte 0x8b in position 1: invalid start byte

During handling of the above exception, another exception occurred:

Traceback (most recent call last):
  File "/usr/src/homeassistant/homeassistant/helpers/entity.py", line 527, in async_update_ha_state
    await self.async_device_update()
  File "/usr/src/homeassistant/homeassistant/helpers/entity.py", line 722, in async_device_update
    raise exc
  File "/config/custom_components/xiaomi_miot/vacuum.py", line 133, in async_update
    await super().async_update()
  File "/config/custom_components/xiaomi_miot/__init__.py", line 1340, in async_update
    results = await self.hass.async_add_executor_job(
  File "/usr/local/lib/python3.10/concurrent/futures/thread.py", line 58, in run
    result = self.fn(*self.args, **self.kwargs)
  File "/config/custom_components/xiaomi_miot/__init__.py", line 653, in get_properties_for_mapping
    return self.get_properties(
  File "/usr/local/lib/python3.10/site-packages/miio/device.py", line 240, in get_properties
    values.extend(self.send(property_getter, _props[:max_properties]))
  File "/usr/local/lib/python3.10/site-packages/miio/device.py", line 107, in send
    return self._protocol.send(
  File "/usr/local/lib/python3.10/site-packages/miio/miioprotocol.py", line 194, in send
    m = Message.parse(data, token=self.token)
  File "/usr/local/lib/python3.10/site-packages/construct/core.py", line 288, in parse
    return self.parse_stream(io.BytesIO(data), **contextkw)
  File "/usr/local/lib/python3.10/site-packages/construct/core.py", line 300, in parse_stream
    return self._parsereport(stream, context, "(parsing)")
  File "/usr/local/lib/python3.10/site-packages/construct/core.py", line 312, in _parsereport
    obj = self._parse(stream, context, path)
  File "/usr/local/lib/python3.10/site-packages/construct/core.py", line 1981, in _parse
    subobj = sc._parsereport(stream, context, path)
  File "/usr/local/lib/python3.10/site-packages/construct/core.py", line 312, in _parsereport
    obj = self._parse(stream, context, path)
  File "/usr/local/lib/python3.10/site-packages/construct/core.py", line 2439, in _parse
    return self.subcon._parsereport(stream, context, path)
  File "/usr/local/lib/python3.10/site-packages/construct/core.py", line 312, in _parsereport
    obj = self._parse(stream, context, path)
  File "/usr/local/lib/python3.10/site-packages/construct/core.py", line 3987, in _parse
    obj = self.subcon._parsereport(stream, context, path)
  File "/usr/local/lib/python3.10/site-packages/construct/core.py", line 312, in _parsereport
    obj = self._parse(stream, context, path)
  File "/usr/local/lib/python3.10/site-packages/construct/core.py", line 4265, in _parse
    obj = self.subcon._parsereport(stream, context, path)
  File "/usr/local/lib/python3.10/site-packages/construct/core.py", line 312, in _parsereport
    obj = self._parse(stream, context, path)
  File "/usr/local/lib/python3.10/site-packages/construct/core.py", line 698, in _parse
    return self._decode(obj, context, path)
  File "/usr/local/lib/python3.10/site-packages/miio/protocol.py", line 204, in _decode
    _LOGGER.debug("Unable to parse json '%s': %s", decoded, ex)
UnboundLocalError: local variable 'decoded' referenced before assignment
2022-11-12 06:33:14.088 ERROR (MainThread) [homeassistant.config] Invalid config for [automation]: Unable to determine action @ data['action'][3]. Got None. (See ?, line ?). 
2022-11-12 06:33:16.458 ERROR (MainThread) [homeassistant.config] Invalid config for [automation]: Unable to determine action @ data['action'][3]. Got None. (See ?, line ?). 
2022-11-12 06:33:31.700 ERROR (MainThread) [homeassistant] Error doing job: Task exception was never retrieved
Traceback (most recent call last):
  File "/usr/local/lib/python3.10/site-packages/snitun/client/client_peer.py", line 137, in _handler
    await self._multiplexer.ping()
  File "/usr/local/lib/python3.10/site-packages/snitun/multiplexer/core.py", line 100, in ping
    self._write_message(
  File "/usr/local/lib/python3.10/site-packages/snitun/multiplexer/core.py", line 205, in _write_message
    raise MultiplexerTransportClose() from None
snitun.exceptions.MultiplexerTransportClose
2022-11-12 06:33:31.705 ERROR (MainThread) [homeassistant.components.hassio.handler] Timeout on /homeassistant/restart request
